Workbook
Name Slicer_admission_type: #N/A
Name Slicer_Age_Group: #N/A
Name Slicer_BMI_Category: #N/A
Name Slicer_gender: #N/A

Sheet Patients by Diagnosis
A3: Row Labels | B3: Count of patient_age
A4: Cardiology | B4: 3491
A5: Endocrinology | B5: 2581
A6: Orthopedics | B6: 1445
A7: Respiratory | B7: 2483
A8: Grand Total | B8: 10000

Sheet Patients by Admission Type
A3: Row Labels | B3: Count of patient_age
A4: Elective | B4: 3073
A5: Emergency | B5: 3925
A6: Urgent | B6: 3002
A7: Grand Total | B7: 10000

Sheet Gender Distribution
A3: Row Labels | B3: Count of patient_age
A4: Female | B4: 5023
A5: Male | B5: 4977
A6: Grand Total | B6: 10000

Sheet Readmission
A3: Row Labels | B3: Count of patient_age
A4: No | B4: 8798
A5: Yes | B5: 1202
A6: Grand Total | B6: 10000

Sheet BMI Category
A3: Row Labels | B3: Count of patient_age
A4: Normal | B4: 3038
A5: Obese | B5: 3084
A6: Overweight | B6: 3503
A7: Underweight | B7: 375
A8: Grand Total | B8: 10000

Sheet healthcare_patients
A1: patient_age | B1: gender | C1: bmi | D1: systolic_bp | E1: diastolic_bp | F1: cholesterol_mg_dl | G1: fasting_blood_sugar | H1: heart_rate_bpm | I1: previous_admissions | J1: admission_type | K1: primary_diagnosis | L1: medication_adherence | M1: length_of_stay_days | N1: treatment_cost_usd | O1: readmission_30_days | P1: Age_Group | Q1: BMI_Category | R1: Blood Pressure Status | S1: Cost Category
A2: 62 | B2: Male | C2: 35.3 | D2: 140 | E2: 83 | F2: 255.7 | G2: 151.2 | H2: 80 | I2: 3 | J2: Elective | K2: Respiratory | L2: Medium | M2: 11.6 | N2: 16478.61 | O2: No | P2: =IF(A3<30,"18-29",IF(A3<45,"30-44",IF(A3<60,"45-59",IF(A3<75,"60-74","75+")))) -> 60-74 | Q2: =IF(PatientData[[#This Row],[bmi]]<18.5,"Underweight", IF(PatientData[[#This Row],[bmi]]<25,"Normal", IF(PatientData[[#This Row],[bmi]]<30,"Overweight","Obese"))) -> Obese | R2: =IF(AND(D2<120,E2<80),"Normal BP","High BP") -> High BP | S2: =IF(N2>15000,"High Cost","Normal Cost") -> High Cost
A3: 62 | B3: Female | C3: 10 | D3: 120 | E3: 75 | F3: 218.9 | G3: 122.4 | H3: 60 | I3: 0 | J3: Elective | K3: Endocrinology | L3: Low | M3: 7.1 | N3: 10867.76 | O3: No | P3: =IF(A3<30,"18-29",IF(A3<45,"30-44",IF(A3<60,"45-59",IF(A3<75,"60-74","75+")))) -> 60-74 | Q3: =IF(PatientData[[#This Row],[bmi]]<18.5,"Underweight", IF(PatientData[[#This Row],[bmi]]<25,"Normal", IF(PatientData[[#This Row],[bmi]]<30,"Overweight","Obese"))) -> Underweight | R3: =IF(AND(D3<120,E3<80),"Normal BP","High BP") -> High BP | S3: =IF(N3>15000,"High Cost","Normal Cost") -> Normal Cost
A4: 58 | B4: Female | C4: 10 | D4: 119 | E4: 77 | F4: 225.9 | G4: 99.9 | H4: 82 | I4: 0 | J4: Urgent | K4: Cardiology | L4: Medium | M4: 4.4 | N4: 10949.07 | O4: No | P4: =IF(A4<30,"18-29",IF(A4<45,"30-44",IF(A4<60,"45-59",IF(A4<75,"60-74","75+")))) -> 45-59 | Q4: =IF(PatientData[[#This Row],[bmi]]<18.5,"Underweight", IF(PatientData[[#This Row],[bmi]]<25,"Normal", IF(PatientData[[#This Row],[bmi]]<30,"Overweight","Obese"))) -> Underweight | R4: =IF(AND(D4<120,E4<80),"Normal BP","High BP") -> Normal BP | S4: =IF(N4>15000,"High Cost","Normal Cost") -> Normal Cost
A5: 85 | B5: Female | C5: 10 | D5: 155 | E5: 92 | F5: 255.3 | G5: 169.8 | H5: 87 | I5: 2 | J5: Emergency | K5: Endocrinology | L5: High | M5: 12.9 | N5: 23216.46 | O5: No | P5: =IF(A5<30,"18-29",IF(A5<45,"30-44",IF(A5<60,"45-59",IF(A5<75,"60-74","75+")))) -> 75+ | Q5: =IF(PatientData[[#This Row],[bmi]]<18.5,"Underweight", IF(PatientData[[#This Row],[bmi]]<25,"Normal", IF(PatientData[[#This Row],[bmi]]<30,"Overweight","Obese"))) -> Underweight | R5: =IF(AND(D5<120,E5<80),"Normal BP","High BP") -> High BP | S5: =IF(N5>15000,"High Cost","Normal Cost") -> High Cost
A6: 55 | B6: Male | C6: 26.6 | D6: 123 | E6: 73 | F6: 193.9 | G6: 126.8 | H6: 68 | I6: 0 | J6: Urgent | K6: Respiratory | L6: Medium | M6: 2 | N6: 5073.79 | O6: No | P6: =IF(A3<30,"18-29",IF(A3<45,"30-44",IF(A3<60,"45-59",IF(A3<75,"60-74","75+")))) -> 60-74 | Q6: =IF(PatientData[[#This Row],[bmi]]<18.5,"Underweight", IF(PatientData[[#This Row],[bmi]]<25,"Normal", IF(PatientData[[#This Row],[bmi]]<30,"Overweight","Obese"))) -> Overweight | R6: =IF(AND(D6<120,E6<80),"Normal BP","High BP") -> High BP | S6: =IF(N6>15000,"High Cost","Normal Cost") -> Normal Cost
A7: 54 | B7: Male | C7: 35.3 | D7: 140 | E7: 83 | F7: 255.7 | G7: 151.2 | H7: 80 | I7: 3 | J7: Elective | K7: Endocrinology | L7: Medium | M7: 2.7 | N7: 6476.72 | O7: No | P7: =IF(A4<30,"18-29",IF(A4<45,"30-44",IF(A4<60,"45-59",IF(A4<75,"60-74","75+")))) -> 45-59 | Q7: =IF(PatientData[[#This Row],[bmi]]<18.5,"Underweight", IF(PatientData[[#This Row],[bmi]]<25,"Normal", IF(PatientData[[#This Row],[bmi]]<30,"Overweight","Obese"))) -> Obese | R7: =IF(AND(D7<120,E7<80),"Normal BP","High BP") -> High BP | S7: =IF(N7>15000,"High Cost","Normal Cost") -> Normal Cost
A8: 61 | B8: Male | C8: 34.2 | D8: 143 | E8: 79 | F8: 257.6 | G8: 141 | H8: 82 | I8: 2 | J8: Emergency | K8: Orthopedics | L8: Low | M8: 8.4 | N8: 18197.84 | O8: Yes | P8: =IF(A5<30,"18-29",IF(A5<45,"30-44",IF(A5<60,"45-59",IF(A5<75,"60-74","75+")))) -> 75+ | Q8: =IF(PatientData[[#This Row],[bmi]]<18.5,"Underweight", IF(PatientData[[#This Row],[bmi]]<25,"Normal", IF(PatientData[[#This Row],[bmi]]<30,"Overweight","Obese"))) -> Obese | R8: =IF(AND(D8<120,E8<80),"Normal BP","High BP") -> High BP | S8: =IF(N8>15000,"High Cost","Normal Cost") -> High Cost
A9: 34 | B9: Female | C9: 10.1 | D9: 121 | E9: 63 | F9: 213.6 | G9: 124.1 | H9: 78 | I9: 2 | J9: Elective | K9: Endocrinology | L9: Medium | M9: 1.8 | N9: 4503.38 | O9: No | P9: =IF(A9<30,"18-29",IF(A9<45,"30-44",IF(A9<60,"45-59",IF(A9<75,"60-74","75+")))) -> 30-44 | Q9: =IF(PatientData[[#This Row],[bmi]]<18.5,"Underweight", IF(PatientData[[#This Row],[bmi]]<25,"Normal", IF(PatientData[[#This Row],[bmi]]<30,"Overweight","Obese"))) -> Underweight | R9: =IF(AND(D9<120,E9<80),"Normal BP","High BP") -> High BP | S9: =IF(N9>15000,"High Cost","Normal Cost") -> Normal Cost
A10: 65 | B10: Female | C10: 10.2 | D10: 113 | E10: 69 | F10: 268.3 | G10: 96.2 | H10: 67 | I10: 0 | J10: Urgent | K10: Respiratory | L10: Medium | M10: 11.6 | N10: 16478.61 | O10: No | P10: =IF(A10<30,"18-29",IF(A10<45,"30-44",IF(A10<60,"45-59",IF(A10<75,"60-74","75+")))) -> 60-74 | Q10: =IF(PatientData[[#This Row],[bmi]]<18.5,"Underweight", IF(PatientData[[#This Row],[bmi]]<25,"Normal", IF(PatientData[[#This Row],[bmi]]<30,"Overweight","Obese"))) -> Underweight | R10: =IF(AND(D10<120,E10<80),"Normal BP","High BP") -> Normal BP | S10: =IF(N10>15000,"High Cost","Normal Cost") -> High Cost
A11: 45 | B11: Female | C11: 10.2 | D11: 102 | E11: 64 | F11: 207 | G11: 139.1 | H11: 80 | I11: 0 | J11: Urgent | K11: Endocrinology | L11: Medium | M11: 6 | N11: 9006.06 | O11: No | P11: =IF(A11<30,"18-29",IF(A11<45,"30-44",IF(A11<60,"45-59",IF(A11<75,"60-74","75+")))) -> 45-59 | Q11: =IF(PatientData[[#This Row],[bmi]]<18.5,"Underweight", IF(PatientData[[#This Row],[bmi]]<25,"Normal", IF(PatientData[[#This Row],[bmi]]<30,"Overweight","Obese"))) -> Underweight | R11: =IF(AND(D11<120,E11<80),"Normal BP","High BP") -> Normal BP | S11: =IF(N11>15000,"High Cost","Normal Cost") -> Normal Cost
A12: 67 | B12: Male | C12: 29.1 | D12: 129 | E12: 82 | F12: 272.8 | G12: 95.3 | H12: 70 | I12: 1 | J12: Elective | K12: Respiratory | L12: Medium | M12: 10.5 | N12: 16593.63 | O12: No | P12: =IF(A9<30,"18-29",IF(A9<45,"30-44",IF(A9<60,"45-59",IF(A9<75,"60-74","75+")))) -> 30-44 | Q12: =IF(PatientData[[#This Row],[bmi]]<18.5,"Underweight", IF(PatientData[[#This Row],[bmi]]<25,"Normal", IF(PatientData[[#This Row],[bmi]]<30,"Overweight","Obese"))) -> Overweight | R12: =IF(AND(D12<120,E12<80),"Normal BP","High BP") -> High BP | S12: =IF(N12>15000,"High Cost","Normal Cost") -> High Cost
A13: 71 | B13: Female | C13: 10.2 | D13: 130 | E13: 72 | F13: 237.4 | G13: 119.6 | H13: 85 | I13: 0 | J13: Emergency | K13: Cardiology | L13: Medium | M13: 9.1 | N13: 19711.46 | O13: No | P13: =IF(A13<30,"18-29",IF(A13<45,"30-44",IF(A13<60,"45-59",IF(A13<75,"60-74","75+")))) -> 60-74 | Q13: =IF(PatientData[[#This Row],[bmi]]<18.5,"Underweight", IF(PatientData[[#This Row],[bmi]]<25,"Normal", IF(PatientData[[#This Row],[bmi]]<30,"Overweight","Obese"))) -> Underweight | R13: =IF(AND(D13<120,E13<80),"Normal BP","High BP") -> High BP | S13: =IF(N13>15000,"High Cost","Normal Cost") -> High Cost
A14: 66 | B14: Female | C14: 10.2 | D14: 121 | E14: 68 | F14: 189.9 | G14: 108.4 | H14: 95 | I14: 2 | J14: Emergency | K14: Endocrinology | L14: Medium | M14: 9 | N14: 15687.54 | O14: No | P14: =IF(A14<30,"18-29",IF(A14<45,"30-44",IF(A14<60,"45-59",IF(A14<75,"60-74","75+")))) -> 60-74 | Q14: =IF(PatientData[[#This Row],[bmi]]<18.5,"Underweight", IF(PatientData[[#This Row],[bmi]]<25,"Normal", IF(PatientData[[#This Row],[bmi]]<30,"Overweight","Obese"))) -> Underweight | R14: =IF(AND(D14<120,E14<80),"Normal BP","High BP") -> High BP | S14: =IF(N14>15000,"High Cost","Normal Cost") -> High Cost
A15: 47 | B15: Male | C15: 30.5 | D15: 114 | E15: 62 | F15: 207.3 | G15: 108.3 | H15: 73 | I15: 3 | J15: Emergency | K15: Cardiology | L15: Medium | M15: 11.7 | N15: 22657.88 | O15: No | P15: =IF(A12<30,"18-29",IF(A12<45,"30-44",IF(A12<60,"45-59",IF(A12<75,"60-74","75+")))) -> 60-74 | Q15: =IF(PatientData[[#This Row],[bmi]]<18.5,"Underweight", IF(PatientData[[#This Row],[bmi]]<25,"Normal", IF(PatientData[[#This Row],[bmi]]<30,"Overweight","Obese"))) -> Obese | R15: =IF(AND(D15<120,E15<80),"Normal BP","High BP") -> Normal BP | S15: =IF(N15>15000,"High Cost","Normal Cost") -> High Cost
A16: 36 | B16: Male | C16: 18 | D16: 96 | E16: 65 | F16: 168.5 | G16: 94.2 | H16: 73 | I16: 2 | J16: Urgent | K16: Cardiology | L16: High | M16: 5 | N16: 10390.56 | O16: No | P16: =IF(A13<30,"18-29",IF(A13<45,"30-44",IF(A13<60,"45-59",IF(A13<75,"60-74","75+")))) -> 60-74 | Q16: =IF(PatientData[[#This Row],[bmi]]<18.5,"Underweight", IF(PatientData[[#This Row],[bmi]]<25,"Normal", IF(PatientData[[#This Row],[bmi]]<30,"Overweight","Obese"))) -> Underweight | R16: =IF(AND(D16<120,E16<80),"Normal BP","High BP") -> Normal BP | S16: =IF(N16>15000,"High Cost","Normal Cost") -> Normal Cost
A17: 52 | B17: Male | C17: 26.4 | D17: 119 | E17: 65 | F17: 243.5 | G17: 134.7 | H17: 77 | I17: 0 | J17: Emergency | K17: Orthopedics | L17: Low | M17: 6.1 | N17: 16611.73 | O17: No | P17: =IF(A14<30,"18-29",IF(A14<45,"30-44",IF(A14<60,"45-59",IF(A14<75,"60-74","75+")))) -> 60-74 | Q17: =IF(PatientData[[#This Row],[bmi]]<18.5,"Underweight", IF(PatientData[[#This Row],[bmi]]<25,"Normal", IF(PatientData[[#This Row],[bmi]]<30,"Overweight","Obese"))) -> Overweight | R17: =IF(AND(D17<120,E17<80),"Normal BP","High BP") -> Normal BP | S17: =IF(N17>15000,"High Cost","Normal Cost") -> High Cost
A18: 71 | B18: Male | C18: 23.8 | D18: 238 | E18: 136 | F18: 230.1 | G18: 123.2 | H18: 88 | I18: 2 | J18: Emergency | K18: Endocrinology | L18: High | M18: 14.9 | N18: 24757.63 | O18: No | P18: =IF(A15<30,"18-29",IF(A15<45,"30-44",IF(A15<60,"45-59",IF(A15<75,"60-74","75+")))) -> 45-59 | Q18: =IF(PatientData[[#This Row],[bmi]]<18.5,"Underweight", IF(PatientData[[#This Row],[bmi]]<25,"Normal", IF(PatientData[[#This Row],[bmi]]<30,"Overweight","Obese"))) -> Normal | R18: =IF(AND(D18<120,E18<80),"Normal BP","High BP") -> High BP | S18: =IF(N18>15000,"High Cost","Normal Cost") -> High Cost
A19: 88 | B19: Female | C19: 10.2 | D19: 135 | E19: 83 | F19: 264.9 | G19: 108.2 | H19: 75 | I19: 2 | J19: Elective | K19: Respiratory | L19: Medium | M19: 7.6 | N19: 13345.22 | O19: No | P19: =IF(A19<30,"18-29",IF(A19<45,"30-44",IF(A19<60,"45-59",IF(A19<75,"60-74","75+")))) -> 75+ | Q19: =IF(PatientData[[#This Row],[bmi]]<18.5,"Underweight", IF(PatientData[[#This Row],[bmi]]<25,"Normal", IF(PatientData[[#This Row],[bmi]]<30,"Overweight","Obese"))) -> Underweight | R19: =IF(AND(D19<120,E19<80),"Normal BP","High BP") -> High BP | S19: =IF(N19>15000,"High Cost","Normal Cost") -> Normal Cost
A20: 66 | B20: Male | C20: 24.7 | D20: 137 | E20: 81 | F20: 247.4 | G20: 86.2 | H20: 83 | I20: 0 | J20: Emergency | K20: Respiratory | L20: Medium | M20: 7.5 | N20: 15754.3 | O20: No | P20: =IF(A17<30,"18-29",IF(A17<45,"30-44",IF(A17<60,"45-59",IF(A17<75,"60-74","75+")))) -> 45-59 | Q20: =IF(PatientData[[#This Row],[bmi]]<18.5,"Underweight", IF(PatientData[[#This Row],[bmi]]<25,"Normal", IF(PatientData[[#This Row],[bmi]]<30,"Overweight","Obese"))) -> Normal | R20: =IF(AND(D20<120,E20<80),"Normal BP","High BP") -> High BP | S20: =IF(N20>15000,"High Cost","Normal Cost") -> High Cost
A21: 47 | B21: Male | C21: 20.2 | D21: 118 | E21: 65 | F21: 209.8 | G21: 93.5 | H21: 85 | I21: 2 | J21: Emergency | K21: Cardiology | L21: High | M21: 11.2 | N21: 18824.2 | O21: No | P21: =IF(A18<30,"18-29",IF(A18<45,"30-44",IF(A18<60,"45-59",IF(A18<75,"60-74","75+")))) -> 60-74 | Q21: =IF(PatientData[[#This Row],[bmi]]<18.5,"Underweight", IF(PatientData[[#This Row],[bmi]]<25,"Normal", IF(PatientData[[#This Row],[bmi]]<30,"Overweight","Obese"))) -> Normal | R21: =IF(AND(D21<120,E21<80),"Normal BP","High BP") -> Normal BP | S21: =IF(N21>15000,"High Cost","Normal Cost") -> High Cost
A22: 95 | B22: Female | C22: 10.4 | D22: 144 | E22: 85 | F22: 282.3 | G22: 131.3 | H22: 69 | I22: 1 | J22: Emergency | K22: Endocrinology | L22: High | M22: 9.1 | N22: 19865.39 | O22: No | P22: =IF(A22<30,"18-29",IF(A22<45,"30-44",IF(A22<60,"45-59",IF(A22<75,"60-74","75+")))) -> 75+ | Q22: =IF(PatientData[[#This Row],[bmi]]<18.5,"Underweight", IF(PatientData[[#This Row],[bmi]]<25,"Normal", IF(PatientData[[#This Row],[bmi]]<30,"Overweight","Obese"))) -> Underweight | R22: =IF(AND(D22<120,E22<80),"Normal BP","High BP") -> High BP | S22: =IF(N22>15000,"High Cost","Normal Cost") -> High Cost
A23: 52 | B23: Male | C23: 18 | D23: 102 | E23: 64 | F23: 226.7 | G23: 185 | H23: 100 | I23: 1 | J23: Emergency | K23: Cardiology | L23: Medium | M23: 8.9 | N23: 19836.46 | O23: No | P23: =IF(A20<30,"18-29",IF(A20<45,"30-44",IF(A20<60,"45-59",IF(A20<75,"60-74","75+")))) -> 60-74 | Q23: =IF(PatientData[[#This Row],[bmi]]<18.5,"Underweight", IF(PatientData[[#This Row],[bmi]]<25,"Normal", IF(PatientData[[#This Row],[bmi]]<30,"Overweight","Obese"))) -> Underweight | R23: =IF(AND(D23<120,E23<80),"Normal BP","High BP") -> Normal BP | S23: =IF(N23>15000,"High Cost","Normal Cost") -> High Cost
A24: 59 | B24: Male | C24: 28 | D24: 138 | E24: 87 | F24: 220.9 | G24: 94.4 | H24: 77 | I24: 1 | J24: Elective | K24: Cardiology | L24: Medium | M24: 12.5 | N24: 21165.81 | O24: No | P24: =IF(A21<30,"18-29",IF(A21<45,"30-44",IF(A21<60,"45-59",IF(A21<75,"60-74","75+")))) -> 45-59 | Q24: =IF(PatientData[[#This Row],[bmi]]<18.5,"Underweight", IF(PatientData[[#This Row],[bmi]]<25,"Normal", IF(PatientData[[#This Row],[bmi]]<30,"Overweight","Obese"))) -> Overweight | R24: =IF(AND(D24<120,E24<80),"Normal BP","High BP") -> High BP | S24: =IF(N24>15000,"High Cost","Normal Cost") -> High Cost
A25: 82 | B25: Male | C25: 22.9 | D25: 131 | E25: 78 | F25: 253.5 | G25: 126.8 | H25: 87 | I25: 3 | J25: Emergency | K25: Endocrinology | L25: Medium | M25: 5 | N25: 11416.67 | O25: Yes | P25: =IF(A22<30,"18-29",IF(A22<45,"30-44",IF(A22<60,"45-59",IF(A22<75,"60-74","75+")))) -> 75+ | Q25: =IF(PatientData[[#This Row],[bmi]]<18.5,"Underweight", IF(PatientData[[#This Row],[bmi]]<25,"Normal", IF(PatientData[[#This Row],[bmi]]<30,"Overweight","Obese"))) -> Normal | R25: =IF(AND(D25<120,E25<80),"Normal BP","High BP") -> High BP | S25: =IF(N25>15000,"High Cost","Normal Cost") -> Normal Cost
A26: 83 | B26: Male | C26: 40.3 | D26: 125 | E26: 78 | F26: 226.4 | G26: 138.2 | H26: 80 | I26: 2 | J26: Elective | K26: Respiratory | L26: Medium | M26: 3 | N26: 5645.35 | O26: No | P26: =IF(A23<30,"18-29",IF(A23<45,"30-44",IF(A23<60,"45-59",IF(A23<75,"60-74","75+")))) -> 45-59 | Q26: =IF(PatientData[[#This Row],[bmi]]<18.5,"Underweight", IF(PatientData[[#This Row],[bmi]]<25,"Normal", IF(PatientData[[#This Row],[bmi]]<30,"Overweight","Obese"))) -> Obese | R26: =IF(AND(D26<120,E26<80),"Normal BP","High BP") -> High BP | S26: =IF(N26>15000,"High Cost","Normal Cost") -> Normal Cost
A27: 57 | B27: Female | C27: 10.4 | D27: 127 | E27: 71 | F27: 234.9 | G27: 117.8 | H27: 97 | I27: 0 | J27: Emergency | K27: Cardiology | L27: Low | M27: 7.1 | N27: 14603.12 | O27: No | P27: =IF(A27<30,"18-29",IF(A27<45,"30-44",IF(A27<60,"45-59",IF(A27<75,"60-74","75+")))) -> 45-59 | Q27: =IF(PatientData[[#This Row],[bmi]]<18.5,"Underweight", IF(PatientData[[#This Row],[bmi]]<25,"Normal", IF(PatientData[[#This Row],[bmi]]<30,"Overweight","Obese"))) -> Underweight | R27: =IF(AND(D27<120,E27<80),"Normal BP","High BP") -> High BP | S27: =IF(N27>15000,"High Cost","Normal Cost") -> Normal Cost
A28: 68 | B28: Male | C28: 18 | D28: 117 | E28: 73 | F28: 221.5 | G28: 93.1 | H28: 79 | I28: 2 | J28: Elective | K28: Cardiology | L28: High | M28: 6.3 | N28: 14342.88 | O28: No | P28: =IF(A25<30,"18-29",IF(A25<45,"30-44",IF(A25<60,"45-59",IF(A25<75,"60-74","75+")))) -> 75+ | Q28: =IF(PatientData[[#This Row],[bmi]]<18.5,"Underweight", IF(PatientData[[#This Row],[bmi]]<25,"Normal", IF(PatientData[[#This Row],[bmi]]<30,"Overweight","Obese"))) -> Underweight | R28: =IF(AND(D28<120,E28<80),"Normal BP","High BP") -> Normal BP | S28: =IF(N28>15000,"High Cost","Normal Cost") -> Normal Cost
A29: 77 | B29: Female | C29: 10.6 | D29: 126 | E29: 74 | F29: 284.3 | G29: 162.4 | H29: 87 | I29: 1 | J29: Emergency | K29: Endocrinology | L29: High | M29: 12.7 | N29: 21207.24 | O29: No | P29: =IF(A29<30,"18-29",IF(A29<45,"30-44",IF(A29<60,"45-59",IF(A29<75,"60-74","75+")))) -> 75+ | Q29: =IF(PatientData[[#This Row],[bmi]]<18.5,"Underweight", IF(PatientData[[#This Row],[bmi]]<25,"Normal", IF(PatientData[[#This Row],[bmi]]<30,"Overweight","Obese"))) -> Underweight | R29: =IF(AND(D29<120,E29<80),"Normal BP","High BP") -> High BP | S29: =IF(N29>15000,"High Cost","Normal Cost") -> High Cost
A30: 60 | B30: Female | C30: 10.6 | D30: 140 | E30: 75 | F30: 225.8 | G30: 152 | H30: 75 | I30: 2 | J30: Urgent | K30: Endocrinology | L30: Medium | M30: 4.8 | N30: 10509.1 | O30: No | P30: =IF(A30<30,"18-29",IF(A30<45,"30-44",IF(A30<60,"45-59",IF(A30<75,"60-74","75+")))) -> 60-74 | Q30: =IF(PatientData[[#This Row],[bmi]]<18.5,"Underweight", IF(PatientData[[#This Row],[bmi]]<25,"Normal", IF(PatientData[[#This Row],[bmi]]<30,"Overweight","Obese"))) -> Underweight | R30: =IF(AND(D30<120,E30<80),"Normal BP","High BP") -> High BP | S30: =IF(N30>15000,"High Cost","Normal Cost") -> Normal Cost
A31: 92 | B31: Male | C31: 33 | D31: 152 | E31: 95 | F31: 249.3 | G31: 138.6 | H31: 82 | I31: 2 | J31: Urgent | K31: Cardiology | L31: High | M31: 5.5 | N31: 14194.93 | O31: Yes | P31: =IF(A28<30,"18-29",IF(A28<45,"30-44",IF(A28<60,"45-59",IF(A28<75,"60-74","75+")))) -> 60-74 | Q31: =IF(PatientData[[#This Row],[bmi]]<18.5,"Underweight", IF(PatientData[[#This Row],[bmi]]<25,"Normal", IF(PatientData[[#This Row],[bmi]]<30,"Overweight","Obese"))) -> Obese | R31: =IF(AND(D31<120,E31<80),"Normal BP","High BP") -> High BP | S31: =IF(N31>15000,"High Cost","Normal Cost") -> Normal Cost
A32: 55 | B32: Female | C32: 10.6 | D32: 111 | E32: 67 | F32: 191.1 | G32: 135.5 | H32: 84 | I32: 0 | J32: Emergency | K32: Respiratory | L32: High | M32: 12.6 | N32: 20095.92 | O32: No | P32: =IF(A32<30,"18-29",IF(A32<45,"30-44",IF(A32<60,"45-59",IF(A32<75,"60-74","75+")))) -> 45-59 | Q32: =IF(PatientData[[#This Row],[bmi]]<18.5,"Underweight", IF(PatientData[[#This Row],[bmi]]<25,"Normal", IF(PatientData[[#This Row],[bmi]]<30,"Overweight","Obese"))) -> Underweight | R32: =IF(AND(D32<120,E32<80),"Normal BP","High BP") -> Normal BP | S32: =IF(N32>15000,"High Cost","Normal Cost") -> High Cost
A33: 37 | B33: Male | C33: 36.4 | D33: 131 | E33: 81 | F33: 214.7 | G33: 120.8 | H33: 66 | I33: 1 | J33: Elective | K33: Cardiology | L33: High | M33: 5.4 | N33: 14085.88 | O33: No | P33: =IF(A30<30,"18-29",IF(A30<45,"30-44",IF(A30<60,"45-59",IF(A30<75,"60-74","75+")))) -> 60-74 | Q33: =IF(PatientData[[#This Row],[bmi]]<18.5,"Underweight", IF(PatientData[[#This Row],[bmi]]<25,"Normal", IF(PatientData[[#This Row],[bmi]]<30,"Overweight","Obese"))) -> Obese | R33: =IF(AND(D33<120,E33<80),"Normal BP","High BP") -> High BP | S33: =IF(N33>15000,"High Cost","Normal Cost") -> Normal Cost
A34: 92 | B34: Male | C34: 28.1 | D34: 150 | E34: 95 | F34: 240.3 | G34: 133.1 | H34: 74 | I34: 2 | J34: Elective | K34: Endocrinology | L34: Low | M34: 1 | N34: 3646.03 | O34: No | P34: =IF(A31<30,"18-29",IF(A31<45,"30-44",IF(A31<60,"45-59",IF(A31<75,"60-74","75+")))) -> 75+ | Q34: =IF(PatientData[[#This Row],[bmi]]<18.5,"Underweight", IF(PatientData[[#This Row],[bmi]]<25,"Normal", IF(PatientData[[#This Row],[bmi]]<30,"Overweight","Obese"))) -> Overweight | R34: =IF(AND(D34<120,E34<80),"Normal BP","High BP") -> High BP | S34: =IF(N34>15000,"High Cost","Normal Cost") -> Normal Cost
A35: 68 | B35: Female | C35: 10.6 | D35: 132 | E35: 75 | F35: 271.1 | G35: 117.2 | H35: 104 | I35: 2 | J35: Elective | K35: Respiratory | L35: Low | M35: 3.4 | N35: 7180.22 | O35: No | P35: =IF(A35<30,"18-29",IF(A35<45,"30-44",IF(A35<60,"45-59",IF(A35<75,"60-74","75+")))) -> 60-74 | Q35: =IF(PatientData[[#This Row],[bmi]]<18.5,"Underweight", IF(PatientData[[#This Row],[bmi]]<25,"Normal", IF(PatientData[[#This Row],[bmi]]<30,"Overweight","Obese"))) -> Underweight | R35: =IF(AND(D35<120,E35<80),"Normal BP","High BP") -> High BP | S35: =IF(N35>15000,"High Cost","Normal Cost") -> Normal Cost
A36: 87 | B36: Female | C36: 10.6 | D36: 128 | E36: 85 | F36: 226.3 | G36: 135 | H36: 110 | I36: 0 | J36: Emergency | K36: Endocrinology | L36: Medium | M36: 14.7 | N36: 22354.85 | O36: No | P36: =IF(A36<30,"18-29",IF(A36<45,"30-44",IF(A36<60,"45-59",IF(A36<75,"60-74","75+")))) -> 75+ | Q36: =IF(PatientData[[#This Row],[bmi]]<18.5,"Underweight", IF(PatientData[[#This Row],[bmi]]<25,"Normal", IF(PatientData[[#This Row],[bmi]]<30,"Overweight","Obese"))) -> Underweight | R36: =IF(AND(D36<120,E36<80),"Normal BP","High BP") -> High BP | S36: =IF(N36>15000,"High Cost","Normal Cost") -> High Cost
A37: 76 | B37: Female | C37: 10.6 | D37: 134 | E37: 76 | F37: 244.3 | G37: 123.4 | H37: 62 | I37: 1 | J37: Urgent | K37: Endocrinology | L37: Medium | M37: 3.4 | N37: 6769 | O37: No | P37: =IF(A37<30,"18-29",IF(A37<45,"30-44",IF(A37<60,"45-59",IF(A37<75,"60-74","75+")))) -> 75+ | Q37: =IF(PatientData[[#This Row],[bmi]]<18.5,"Underweight", IF(PatientData[[#This Row],[bmi]]<25,"Normal", IF(PatientData[[#This Row],[bmi]]<30,"Overweight","Obese"))) -> Underweight | R37: =IF(AND(D37<120,E37<80),"Normal BP","High BP") -> High BP | S37: =IF(N37>15000,"High Cost","Normal Cost") -> Normal Cost
A38: 77 | B38: Male | C38: 33.6 | D38: 138 | E38: 83 | F38: 255.3 | G38: 110.9 | H38: 82 | I38: 0 | J38: Elective | K38: Respiratory | L38: Low | M38: 3 | N38: 6519.84 | O38: No | P38: =IF(A35<30,"18-29",IF(A35<45,"30-44",IF(A35<60,"45-59",IF(A35<75,"60-74","75+")))) -> 60-74 | Q38: =IF(PatientData[[#This Row],[bmi]]<18.5,"Underweight", IF(PatientData[[#This Row],[bmi]]<25,"Normal", IF(PatientData[[#This Row],[bmi]]<30,"Overweight","Obese"))) -> Obese | R38: =IF(AND(D38<120,E38<80),"Normal BP","High BP") -> High BP | S38: =IF(N38>15000,"High Cost","Normal Cost") -> Normal Cost
A39: 45 | B39: Male | C39: 21.2 | D39: 134 | E39: 90 | F39: 209.3 | G39: 125.5 | H39: 89 | I39: 3 | J39: Emergency | K39: Cardiology | L39: High | M39: 24 | N39: 37678.12 | O39: No | P39: =IF(A36<30,"18-29",IF(A36<45,"30-44",IF(A36<60,"45-59",IF(A36<75,"60-74","75+")))) -> 75+ | Q39: =IF(PatientData[[#This Row],[bmi]]<18.5,"Underweight", IF(PatientData[[#This Row],[bmi]]<25,"Normal", IF(PatientData[[#This Row],[bmi]]<30,"Overweight","Obese"))) -> Normal | R39: =IF(AND(D39<120,E39<80),"Normal BP","High BP") -> High BP | S39: =IF(N39>15000,"High Cost","Normal Cost") -> High Cost
A40: 68 | B40: Female | C40: 10.7 | D40: 126 | E40: 65 | F40: 229.2 | G40: 124.3 | H40: 76 | I40: 2 | J40: Emergency | K40: Respiratory | L40: Medium | M40: 7.5 | N40: 13142.59 | O40: No | P40: =IF(A40<30,"18-29",IF(A40<45,"30-44",IF(A40<60,"45-59",IF(A40<75,"60-74","75+")))) -> 60-74 | Q40: =IF(PatientData[[#This Row],[bmi]]<18.5,"Underweight", IF(PatientData[[#This Row],[bmi]]<25,"Normal", IF(PatientData[[#This Row],[bmi]]<30,"Overweight","Obese"))) -> Underweight | R40: =IF(AND(D40<120,E40<80),"Normal BP","High BP") -> High BP | S40: =IF(N40>15000,"High Cost","Normal Cost") -> Normal Cost
...

Sheet KPI
A1: KPI Name | B1: Value
A2: Total Patients | B2: =COUNTA(PatientData[patient_age]) -> 10000
A3: Average Age | B3: =AVERAGE(PatientData[patient_age]) -> 64.7691
A4: Average BMI | B4: =AVERAGE(PatientData[bmi]) -> 27.53847
A5: Average Treatment Cost | B5: =AVERAGE(PatientData[treatment_cost_usd]) -> 14530.785
A6: Average Length of Stay | B6: =AVERAGE(PatientData[length_of_stay_days]) -> 7.29183
A7: Readmission Count | B7: =COUNTIF(PatientData[readmission_30_days],"Yes") -> 1202
A8: Readmission Rate | B8: =COUNTIF(PatientData[readmission_30_days],"Yes")/COUNTA(PatientData[patient_age]) -> 0.1202

Sheet Dashboard
A1: Healthcare Patient Analysis Dashboard
A3: Total Patients | F3: Average Age | K3: Average BMI | P3: Average Treatment Cost | U3: Average Length of Stay | Z3: Readmission Rate
A4: =KPI!B2 -> 10000 | F4: =KPI!B3 -> 64.7691 | K4: =KPI!B4 -> 27.53847 | P4: =KPI!B5 -> 14530.785 | U4: =KPI!B6 -> 7.29183 | Z4: =KPI!B8 -> 0.1202
A37: Healthcare Patient Analysis Dashboard Created by: Rakshitha Sudharshna Tools Used: Advanced Excel | PivotTables | PivotCharts | Slicers | Dashboard | Data Analysis
